Run
Pod
MANAGE
Lucario SD API
5x7p7xb447nwfk
2
Workers
0
Min
3
Max
0
Queued
0
InProgress
13
Completed
0
Failed
1
Retried
16
GB VRAM GPU
Running
2
Workers
Worker Uptime: 27s
RTX A4000
28 seconds ago
Worker Utilization
CPU
0%
Mem
22%
GPU Utilization
0
0%
GPU Memory Used
0
21%
RUN
https://api.runpod.ai/v1/5x7p7xb447nwfk/run
STATUS
https://api.runpod.ai/v1/5x7p7xb447nwfk/status/:id
0.00040/s
Â© RunPod 2023
My APIs
Search

0 matches
2023-03-22T00:13:43.748891095Z Container Started
2023-03-22T00:13:43.753315273Z --2023-03-22 00:13:43--  http://workspace/stable-diffusion-webui/webui.py
2023-03-22T00:13:43.799704139Z Resolving workspace (workspace)... failed: Temporary failure in name resolution.
2023-03-22T00:13:43.799748070Z wget: unable to resolve host address 'workspace'
2023-03-22T00:13:43.799754380Z --2023-03-22 00:13:43--  https://gist.githubusercontent.com/potaycat/b3713e593dbe9b3570beea6239356f1d/raw/917b2c3fb6a8068ae39b6b688110391ef3eb767d/webui.py
2023-03-22T00:13:43.819309285Z Resolving gist.githubusercontent.com (gist.githubusercontent.com)... 185.199.108.133, 185.199.109.133, 185.199.110.133, ...
2023-03-22T00:13:43.827519698Z Connecting to gist.githubusercontent.com (gist.githubusercontent.com)|185.199.108.133|:443... connected.
2023-03-22T00:13:43.852325416Z HTTP request sent, awaiting response... 200 OK
2023-03-22T00:13:43.852335586Z Length: 11741 (11K) [text/plain]
2023-03-22T00:13:43.852337996Z Saving to: 'N'
2023-03-22T00:13:43.852354286Z 
2023-03-22T00:13:43.852620548Z      0K .......... .                                          100% 31.8M=0s
2023-03-22T00:13:43.852641858Z 
2023-03-22T00:13:43.852657388Z 2023-03-22 00:13:43 (31.8 MB/s) - 'N' saved [11741/11741]
2023-03-22T00:13:43.852663028Z 
2023-03-22T00:13:43.852665298Z FINISHED --2023-03-22 00:13:43--
2023-03-22T00:13:43.852667758Z Total wall clock time: 0.1s
2023-03-22T00:13:43.852669518Z Downloaded: 1 files, 11K in 0s (31.8 MB/s)
2023-03-22T00:13:43.856846405Z starting api
2023-03-22T00:13:43.857720871Z starting worker
2023-03-22T00:13:43.981757394Z INFO   | RUNPOD_AI_API_KEY: V**************************************N
2023-03-22T00:13:43.981781274Z INFO   | RUNPOD_WEBHOOK_GET_JOB: h**********************************************************************************0
2023-03-22T00:13:43.981786734Z INFO   | RUNPOD_WEBHOOK_POST_OUTPUT: h**************************************************************************************0
2023-03-22T00:13:44.189852165Z API is not available, retrying in 200ms... (HTTPConnectionPool(host='127.0.0.1', port=3000): Max retries exceeded with url: /sdapi/v1/txt2img (Caused by NewConnectionError('<urllib3.connection.HTTPConnection object at 0x7f0eae5c86d0>: Failed to establish a new connection: [Errno 111] Connection refused')))
2023-03-22T00:13:44.391722786Z API is not available, retrying in 200ms... (HTTPConnectionPool(host='127.0.0.1', port=3000): Max retries exceeded with url: /sdapi/v1/txt2img (Caused by NewConnectionError('<urllib3.connection.HTTPConnection object at 0x7f0eae5c8e80>: Failed to establish a new connection: [Errno 111] Connection refused')))
2023-03-22T00:13:44.593006923Z API is not available, retrying in 200ms... (HTTPConnectionPool(host='127.0.0.1', port=3000): Max retries exceeded with url: /sdapi/v1/txt2img (Caused by NewConnectionError('<urllib3.connection.HTTPConnection object at 0x7f0eae5c95d0>: Failed to establish a new connection: [Errno 111] Connection refused')))
2023-03-22T00:13:44.795010155Z API is not available, retrying in 200ms... (HTTPConnectionPool(host='127.0.0.1', port=3000): Max retries exceeded with url: /sdapi/v1/txt2img (Caused by NewConnectionError('<urllib3.connection.HTTPConnection object at 0x7f0eae5c9d20>: Failed to establish a new connection: [Errno 111] Connection refused')))
2023-03-22T00:13:44.997032767Z API is not available, retrying in 200ms... (HTTPConnectionPool(host='127.0.0.1', port=3000): Max retries exceeded with url: /sdapi/v1/txt2img (Caused by NewConnectionError('<urllib3.connection.HTTPConnection object at 0x7f0eae5ca470>: Failed to establish a new connection: [Errno 111] Connection refused')))
2023-03-22T00:13:45.199165440Z API is not available, retrying in 200ms... (HTTPConnectionPool(host='127.0.0.1', port=3000): Max retries exceeded with url: /sdapi/v1/txt2img (Caused by NewConnectionError('<urllib3.connection.HTTPConnection object at 0x7f0eae5ca920>: Failed to establish a new connection: [Errno 111] Connection refused')))
2023-03-22T00:13:45.401043412Z API is not available, retrying in 200ms... (HTTPConnectionPool(host='127.0.0.1', port=3000): Max retries exceeded with url: /sdapi/v1/txt2img (Caused by NewConnectionError('<urllib3.connection.HTTPConnection object at 0x7f0eae5c9a80>: Failed to establish a new connection: [Errno 111] Connection refused')))
2023-03-22T00:13:45.602932882Z API is not available, retrying in 200ms... (HTTPConnectionPool(host='127.0.0.1', port=3000): Max retries exceeded with url: /sdapi/v1/txt2img (Caused by NewConnectionError('<urllib3.connection.HTTPConnection object at 0x7f0eae5c9330>: Failed to establish a new connection: [Errno 111] Connection refused')))
2023-03-22T00:13:45.804954774Z API is not available, retrying in 200ms... (HTTPConnectionPool(host='127.0.0.1', port=3000): Max retries exceeded with url: /sdapi/v1/txt2img (Caused by NewConnectionError('<urllib3.connection.HTTPConnection object at 0x7f0eae5c8be0>: Failed to establish a new connection: [Errno 111] Connection refused')))
2023-03-22T00:13:46.006831336Z API is not available, retrying in 200ms... (HTTPConnectionPool(host='127.0.0.1', port=3000): Max retries exceeded with url: /sdapi/v1/txt2img (Caused by NewConnectionError('<urllib3.connection.HTTPConnection object at 0x7f0eae5c82b0>: Failed to establish a new connection: [Errno 111] Connection refused')))
2023-03-22T00:13:46.208748817Z API is not available, retrying in 200ms... (HTTPConnectionPool(host='127.0.0.1', port=3000): Max retries exceeded with url: /sdapi/v1/txt2img (Caused by NewConnectionError('<urllib3.connection.HTTPConnection object at 0x7f0eae5cabc0>: Failed to establish a new connection: [Errno 111] Connection refused')))
2023-03-22T00:13:46.412507740Z API is not available, retrying in 200ms... (HTTPConnectionPool(host='127.0.0.1', port=3000): Max retries exceeded with url: /sdapi/v1/txt2img (Caused by NewConnectionError('<urllib3.connection.HTTPConnection object at 0x7f0eae5cb310>: Failed to establish a new connection: [Errno 111] Connection refused')))
2023-03-22T00:13:46.622933757Z API is not available, retrying in 200ms... (HTTPConnectionPool(host='127.0.0.1', port=3000): Max retries exceeded with url: /sdapi/v1/txt2img (Caused by NewConnectionError('<urllib3.connection.HTTPConnection object at 0x7f0eae5c83d0>: Failed to establish a new connection: [Errno 111] Connection refused')))
2023-03-22T00:13:46.824142884Z API is not available, retrying in 200ms... (HTTPConnectionPool(host='127.0.0.1', port=3000): Max retries exceeded with url: /sdapi/v1/txt2img (Caused by NewConnectionError('<urllib3.connection.HTTPConnection object at 0x7f0eae5c8e20>: Failed to establish a new connection: [Errno 111] Connection refused')))
2023-03-22T00:13:47.026177275Z API is not available, retrying in 200ms... (HTTPConnectionPool(host='127.0.0.1', port=3000): Max retries exceeded with url: /sdapi/v1/txt2img (Caused by NewConnectionError('<urllib3.connection.HTTPConnection object at 0x7f0eae5c9570>: Failed to establish a new connection: [Errno 111] Connection refused')))
2023-03-22T00:13:47.228188607Z API is not available, retrying in 200ms... (HTTPConnectionPool(host='127.0.0.1', port=3000): Max retries exceeded with url: /sdapi/v1/txt2img (Caused by NewConnectionError('<urllib3.connection.HTTPConnection object at 0x7f0eae5c9cc0>: Failed to establish a new connection: [Errno 111] Connection refused')))
2023-03-22T00:13:47.430118639Z API is not available, retrying in 200ms... (HTTPConnectionPool(host='127.0.0.1', port=3000): Max retries exceeded with url: /sdapi/v1/txt2img (Caused by NewConnectionError('<urllib3.connection.HTTPConnection object at 0x7f0eae5ca380>: Failed to establish a new connection: [Errno 111] Connection refused')))
2023-03-22T00:13:47.632143741Z API is not available, retrying in 200ms... (HTTPConnectionPool(host='127.0.0.1', port=3000): Max retries exceeded with url: /sdapi/v1/txt2img (Caused by NewConnectionError('<urllib3.connection.HTTPConnection object at 0x7f0eae5ca710>: Failed to establish a new connection: [Errno 111] Connection refused')))
2023-03-22T00:13:47.834632966Z API is not available, retrying in 200ms... (HTTPConnectionPool(host='127.0.0.1', port=3000): Max retries exceeded with url: /sdapi/v1/txt2img (Caused by NewConnectionError('<urllib3.connection.HTTPConnection object at 0x7f0eae5ca200>: Failed to establish a new connection: [Errno 111] Connection refused')))
2023-03-22T00:13:48.036742480Z API is not available, retrying in 200ms... (HTTPConnectionPool(host='127.0.0.1', port=3000): Max retries exceeded with url: /sdapi/v1/txt2img (Caused by NewConnectionError('<urllib3.connection.HTTPConnection object at 0x7f0eae5ca440>: Failed to establish a new connection: [Errno 111] Connection refused')))
2023-03-22T00:13:48.238910262Z API is not available, retrying in 200ms... (HTTPConnectionPool(host='127.0.0.1', port=3000): Max retries exceeded with url: /sdapi/v1/txt2img (Caused by NewConnectionError('<urllib3.connection.HTTPConnection object at 0x7f0eae5c9d20>: Failed to establish a new connection: [Errno 111] Connection refused')))
2023-03-22T00:13:48.440808633Z API is not available, retrying in 200ms... (HTTPConnectionPool(host='127.0.0.1', port=3000): Max retries exceeded with url: /sdapi/v1/txt2img (Caused by NewConnectionError('<urllib3.connection.HTTPConnection object at 0x7f0eae5c95d0>: Failed to establish a new connection: [Errno 111] Connection refused')))
2023-03-22T00:13:48.642665795Z API is not available, retrying in 200ms... (HTTPConnectionPool(host='127.0.0.1', port=3000): Max retries exceeded with url: /sdapi/v1/txt2img (Caused by NewConnectionError('<urllib3.connection.HTTPConnection object at 0x7f0eae5c8e80>: Failed to establish a new connection: [Errno 111] Connection refused')))
2023-03-22T00:13:48.844671247Z API is not available, retrying in 200ms... (HTTPConnectionPool(host='127.0.0.1', port=3000): Max retries exceeded with url: /sdapi/v1/txt2img (Caused by NewConnectionError('<urllib3.connection.HTTPConnection object at 0x7f0eae5cb160>: Failed to establish a new connection: [Errno 111] Connection refused')))
2023-03-22T00:13:49.047296912Z API is not available, retrying in 200ms... (HTTPConnectionPool(host='127.0.0.1', port=3000): Max retries exceeded with url: /sdapi/v1/txt2img (Caused by NewConnectionError('<urllib3.connection.HTTPConnection object at 0x7f0eae5cacb0>: Failed to establish a new connection: [Errno 111] Connection refused')))
2023-03-22T00:13:49.249380915Z API is not available, retrying in 200ms... (HTTPConnectionPool(host='127.0.0.1', port=3000): Max retries exceeded with url: /sdapi/v1/txt2img (Caused by NewConnectionError('<urllib3.connection.HTTPConnection object at 0x7f0eae5c85e0>: Failed to establish a new connection: [Errno 111] Connection refused')))
2023-03-22T00:13:49.451612228Z Calculating sha256 for /workspace/stable-diffusion-webui/models/Stable-diffusion/anything-v4.5-pruned.safetensors: API is not available, retrying in 200ms... (HTTPConnectionPool(host='127.0.0.1', port=3000): Max retries exceeded with url: /sdapi/v1/txt2img (Caused by NewConnectionError('<urllib3.connection.HTTPConnection object at 0x7f0eae5c8d60>: Failed to establish a new connection: [Errno 111] Connection refused')))
2023-03-22T00:13:49.653655570Z API is not available, retrying in 200ms... (HTTPConnectionPool(host='127.0.0.1', port=3000): Max retries exceeded with url: /sdapi/v1/txt2img (Caused by NewConnectionError('<urllib3.connection.HTTPConnection object at 0x7f0eae5c94b0>: Failed to establish a new connection: [Errno 111] Connection refused')))
2023-03-22T00:13:49.855836483Z API is not available, retrying in 200ms... (HTTPConnectionPool(host='127.0.0.1', port=3000): Max retries exceeded with url: /sdapi/v1/txt2img (Caused by NewConnectionError('<urllib3.connection.HTTPConnection object at 0x7f0eae5c9c00>: Failed to establish a new connection: [Errno 111] Connection refused')))
2023-03-22T00:13:50.057854506Z API is not available, retrying in 200ms... (HTTPConnectionPool(host='127.0.0.1', port=3000): Max retries exceeded with url: /sdapi/v1/txt2img (Caused by NewConnectionError('<urllib3.connection.HTTPConnection object at 0x7f0eae5ca1d0>: Failed to establish a new connection: [Errno 111] Connection refused')))
2023-03-22T00:13:50.260393811Z API is not available, retrying in 200ms... (HTTPConnectionPool(host='127.0.0.1', port=3000): Max retries exceeded with url: /sdapi/v1/txt2img (Caused by NewConnectionError('<urllib3.connection.HTTPConnection object at 0x7f0eae5cb6d0>: Failed to establish a new connection: [Errno 111] Connection refused')))
2023-03-22T00:13:50.462791716Z API is not available, retrying in 200ms... (HTTPConnectionPool(host='127.0.0.1', port=3000): Max retries exceeded with url: /sdapi/v1/txt2img (Caused by NewConnectionError('<urllib3.connection.HTTPConnection object at 0x7f0eae5cb820>: Failed to establish a new connection: [Errno 111] Connection refused')))
2023-03-22T00:13:50.664692928Z API is not available, retrying in 200ms... (HTTPConnectionPool(host='127.0.0.1', port=3000): Max retries exceeded with url: /sdapi/v1/txt2img (Caused by NewConnectionError('<urllib3.connection.HTTPConnection object at 0x7f0eae5ca7a0>: Failed to establish a new connection: [Errno 111] Connection refused')))
2023-03-22T00:13:50.866687509Z API is not available, retrying in 200ms... (HTTPConnectionPool(host='127.0.0.1', port=3000): Max retries exceeded with url: /sdapi/v1/txt2img (Caused by NewConnectionError('<urllib3.connection.HTTPConnection object at 0x7f0eae5c9930>: Failed to establish a new connection: [Errno 111] Connection refused')))
2023-03-22T00:13:51.068619820Z API is not available, retrying in 200ms... (HTTPConnectionPool(host='127.0.0.1', port=3000): Max retries exceeded with url: /sdapi/v1/txt2img (Caused by NewConnectionError('<urllib3.connection.HTTPConnection object at 0x7f0eae5c91e0>: Failed to establish a new connection: [Errno 111] Connection refused')))
2023-03-22T00:13:51.270496792Z API is not available, retrying in 200ms... (HTTPConnectionPool(host='127.0.0.1', port=3000): Max retries exceeded with url: /sdapi/v1/txt2img (Caused by NewConnectionError('<urllib3.connection.HTTPConnection object at 0x7f0eae5c8a90>: Failed to establish a new connection: [Errno 111] Connection refused')))
2023-03-22T00:13:51.474780748Z API is not available, retrying in 200ms... (HTTPConnectionPool(host='127.0.0.1', port=3000): Max retries exceeded with url: /sdapi/v1/txt2img (Caused by NewConnectionError('<urllib3.connection.HTTPConnection object at 0x7f0eae5c8100>: Failed to establish a new connection: [Errno 111] Connection refused')))
2023-03-22T00:13:51.683196461Z API is not available, retrying in 200ms... (HTTPConnectionPool(host='127.0.0.1', port=3000): Max retries exceeded with url: /sdapi/v1/txt2img (Caused by NewConnectionError('<urllib3.connection.HTTPConnection object at 0x7f0eae5cba60>: Failed to establish a new connection: [Errno 111] Connection refused')))
2023-03-22T00:13:51.880830995Z API is not available, retrying in 200ms... (HTTPConnectionPool(host='127.0.0.1', port=3000): Max retries exceeded with url: /sdapi/v1/txt2img (Caused by NewConnectionError('<urllib3.connection.HTTPConnection object at 0x7f0eae5c90c0>: Failed to establish a new connection: [Errno 111] Connection refused')))
2023-03-22T00:13:52.082752126Z API is not available, retrying in 200ms... (HTTPConnectionPool(host='127.0.0.1', port=3000): Max retries exceeded with url: /sdapi/v1/txt2img (Caused by NewConnectionError('<urllib3.connection.HTTPConnection object at 0x7f0eae5c9810>: Failed to establish a new connection: [Errno 111] Connection refused')))
2023-03-22T00:13:52.284687918Z API is not available, retrying in 200ms... (HTTPConnectionPool(host='127.0.0.1', port=3000): Max retries exceeded with url: /sdapi/v1/txt2img (Caused by NewConnectionError('<urllib3.connection.HTTPConnection object at 0x7f0eae5ca290>: Failed to establish a new connection: [Errno 111] Connection refused')))
2023-03-22T00:13:52.408111818Z 6e430eb51421ce5bf18f04e2dbe90b2cad437311948be4ef8c33658a73c86b2a
2023-03-22T00:13:52.408557220Z Loading weights [6e430eb514] from /workspace/stable-diffusion-webui/models/Stable-diffusion/anything-v4.5-pruned.safetensors
2023-03-22T00:13:52.443380053Z Creating model from config: /workspace/stable-diffusion-webui/configs/v1-inference.yaml
2023-03-22T00:13:52.443837975Z LatentDiffusion: Running in eps-prediction mode
2023-03-22T00:13:52.486684040Z API is not available, retrying in 200ms... (HTTPConnectionPool(host='127.0.0.1', port=3000): Max retries exceeded with url: /sdapi/v1/txt2img (Caused by NewConnectionError('<urllib3.connection.HTTPConnection object at 0x7f0eae5ca5c0>: Failed to establish a new connection: [Errno 111] Connection refused')))
2023-03-22T00:13:52.514538968Z DiffusionWrapper has 859.52 M params.
2023-03-22T00:13:52.688355439Z API is not available, retrying in 200ms... (HTTPConnectionPool(host='127.0.0.1', port=3000): Max retries exceeded with url: /sdapi/v1/txt2img (Caused by NewConnectionError('<urllib3.connection.HTTPConnection object at 0x7f0eae5ca020>: Failed to establish a new connection: [Errno 111] Connection refused')))
2023-03-22T00:13:52.890495203Z API is not available, retrying in 200ms... (HTTPConnectionPool(host='127.0.0.1', port=3000): Max retries exceeded with url: /sdapi/v1/txt2img (Caused by NewConnectionError('<urllib3.connection.HTTPConnection object at 0x7f0eae5ca5f0>: Failed to establish a new connection: [Errno 111] Connection refused')))
2023-03-22T00:13:53.092745236Z API is not available, retrying in 200ms... (HTTPConnectionPool(host='127.0.0.1', port=3000): Max retries exceeded with url: /sdapi/v1/txt2img (Caused by NewConnectionError('<urllib3.connection.HTTPConnection object at 0x7f0eae5cb760>: Failed to establish a new connection: [Errno 111] Connection refused')))
2023-03-22T00:13:53.294093873Z API is not available, retrying in 200ms... (HTTPConnectionPool(host='127.0.0.1', port=3000): Max retries exceeded with url: /sdapi/v1/txt2img (Caused by NewConnectionError('<urllib3.connection.HTTPConnection object at 0x7f0eae5c9f30>: Failed to establish a new connection: [Errno 111] Connection refused')))
2023-03-22T00:13:53.496180677Z API is not available, retrying in 200ms... (HTTPConnectionPool(host='127.0.0.1', port=3000): Max retries exceeded with url: /sdapi/v1/txt2img (Caused by NewConnectionError('<urllib3.connection.HTTPConnection object at 0x7f0eae5c9db0>: Failed to establish a new connection: [Errno 111] Connection refused')))
2023-03-22T00:13:53.698109227Z API is not available, retrying in 200ms... (HTTPConnectionPool(host='127.0.0.1', port=3000): Max retries exceeded with url: /sdapi/v1/txt2img (Caused by NewConnectionError('<urllib3.connection.HTTPConnection object at 0x7f0eae5c9780>: Failed to establish a new connection: [Errno 111] Connection refused')))
2023-03-22T00:13:53.900119130Z API is not available, retrying in 200ms... (HTTPConnectionPool(host='127.0.0.1', port=3000): Max retries exceeded with url: /sdapi/v1/txt2img (Caused by NewConnectionError('<urllib3.connection.HTTPConnection object at 0x7f0eae5c9030>: Failed to establish a new connection: [Errno 111] Connection refused')))
2023-03-22T00:13:54.102020701Z API is not available, retrying in 200ms... (HTTPConnectionPool(host='127.0.0.1', port=3000): Max retries exceeded with url: /sdapi/v1/txt2img (Caused by NewConnectionError('<urllib3.connection.HTTPConnection object at 0x7f0eae5c91b0>: Failed to establish a new connection: [Errno 111] Connection refused')))
2023-03-22T00:13:54.304303774Z API is not available, retrying in 200ms... (HTTPConnectionPool(host='127.0.0.1', port=3000): Max retries exceeded with url: /sdapi/v1/txt2img (Caused by NewConnectionError('<urllib3.connection.HTTPConnection object at 0x7f0eae5fc1f0>: Failed to establish a new connection: [Errno 111] Connection refused')))
2023-03-22T00:13:54.438816634Z Applying xformers cross attention optimization.
2023-03-22T00:13:54.445383157Z Textual inversion embeddings loaded(0): 
2023-03-22T00:13:54.448159545Z Model loaded in 5.1s (calculate hash: 3.0s, create model: 0.4s, apply weights to model: 0.2s, apply half(): 0.2s, load VAE: 0.9s, move model to device: 0.3s).
2023-03-22T00:13:54.506213316Z API is not available, retrying in 200ms... (HTTPConnectionPool(host='127.0.0.1', port=3000): Max retries exceeded with url: /sdapi/v1/txt2img (Caused by NewConnectionError('<urllib3.connection.HTTPConnection object at 0x7f0eae5c8c10>: Failed to establish a new connection: [Errno 111] Connection refused')))
2023-03-22T00:13:54.699084829Z Startup time: 9.7s (import gradio: 2.2s, import ldm: 0.5s, other imports: 1.2s, load scripts: 0.4s, load SD checkpoint: 5.2s).
2023-03-22T00:13:54.708107298Z API is not available, retrying in 200ms... (HTTPConnectionPool(host='127.0.0.1', port=3000): Max retries exceeded with url: /sdapi/v1/txt2img (Caused by NewConnectionError('<urllib3.connection.HTTPConnection object at 0x7f0eae5c9360>: Failed to establish a new connection: [Errno 111] Connection refused')))
2023-03-22T00:13:54.710748494Z INFO:     Started server process [9]
2023-03-22T00:13:54.710765514Z INFO:     Waiting for application startup.
2023-03-22T00:13:54.710770544Z INFO:     Application startup complete.
2023-03-22T00:13:54.711532330Z INFO:     Uvicorn running on http://127.0.0.1:3000 (Press CTRL+C to quit)
2023-03-22T00:13:54.918579045Z INFO:     127.0.0.1:41788 - "GET /sdapi/v1/txt2img HTTP/1.1" 405 Method Not Allowed
2023-03-22T00:13:54.919960783Z run handler
2023-03-22T00:13:55.103185786Z INFO   | Heartbeat Sent  URL: https://api.runpod.ai/v1/5x7p7xb447nwfk/ping/t778twx9s0fzpx?gpu=NVIDIA+RTX+A4000  Status: 404
2023-03-22T00:13:55.103215936Z INFO   | Heartbeat Sent  Interval: 4000ms  Params: None
2023-03-22T00:13:55.535362089Z INFO   | {'delayTime': 16033, 'id': '980b7905-4204-4ea5-85fc-f71df9cab889', 'input': {'cfg_scale': 7, 'negative_prompt': 'easynegative, bad_prompt, normal quality, bad quality, incorrect limb', 'prompt': 'lucario wearing pink socks, detailed,  <lora:Lucario:0.7>, red eyes, stripe stockings, stripe socks, spikes, soft smile, anatomy correct limb, ambient lights, teeth, wolf, medium muzzle, pokemon, blue fur', 'sd_lora': 'Lucario', 'seed': 1606412815, 'steps': 20}, 'status': 'IN_PROGRESS'}
2023-03-22T00:13:55.535400610Z INFO   | Started working on 980b7905-4204-4ea5-85fc-f71df9cab889 at 1679444035.535082 UTC
2023-03-22T00:13:55.535406161Z got event
2023-03-22T00:13:55.535410221Z {'delayTime': 16033, 'id': '980b7905-4204-4ea5-85fc-f71df9cab889', 'input': {'cfg_scale': 7, 'negative_prompt': 'easynegative, bad_prompt, normal quality, bad quality, incorrect limb', 'prompt': 'lucario wearing pink socks, detailed,  <lora:Lucario:0.7>, red eyes, stripe stockings, stripe socks, spikes, soft smile, anatomy correct limb, ambient lights, teeth, wolf, medium muzzle, pokemon, blue fur', 'sd_lora': 'Lucario', 'seed': 1606412815, 'steps': 20}, 'status': 'IN_PROGRESS'}
2023-03-22T00:13:55.872206974Z Skipping unknown extra network: lora
2023-03-22T00:13:57.292839351Z 
2023-03-22T00:13:57.444330789Z 
Total progress:   0%|          | 0/20 [00:00<?, ?it/s]
2023-03-22T00:13:57.595287126Z 
Total progress:  15%|ââ        | 3/20 [00:00<00:00, 19.82it/s]